<?xml version="1.0"?>
<!-- created with Phobos 0.7 -->
  <robot name="audibot" xmlns:xacro="http://www.ros.org/wiki/xacro">

  <xacro:include filename="$(find audibot_description)/urdf/audibot_friction.urdf"/>
  <xacro:include filename="$(find audibot_description)/urdf/audibot_control.urdf"/>

  <xacro:if value="$(arg use_sensors)" >
    <xacro:include filename="$(find audibot_description)/urdf/audibot_sensors.urdf.xacro"/>
  </xacro:if>

  <xacro:macro name="gps_antenna" params="link_name x y z" >
    <link name="${link_name}" >
      <visual>
        <origin xyz="0 0 0" rpy="0 0 0" />
        <geometry>
          <cylinder radius="0.1" length="0.05" />
        </geometry>
        <material name="white" >
          <color rgba="1 1 1 1" />
        </material>
      </visual>
      <collision>
        <origin xyz="0 0 0" rpy="0 0 0" />
        <geometry>
          <cylinder radius="0.1" length="0.05" />
        </geometry>
      </collision>
      <inertial>
        <origin xyz="0 0 0" rpy="0 0 0"/>
        <mass value="1.0"/>
        <inertia ixx="0.037227" ixy="0" ixz="0" iyy="0.037227" iyz="0" izz="0.063878"/>
      </inertial>
    </link>
    <joint name="${link_name}" type="fixed" >
      <origin xyz="${x} ${y} ${z}" rpy="0 0 0" />
      <parent link="base_footprint" />
      <child link="${link_name}" />
    </joint>
    <gazebo>
      <plugin name="gps_plugin" filename="libgps_plugin.so" >
        <link_name>${link_name}</link_name>
        <ant_offset_x>${x}</ant_offset_x>
        <ant_offset_y>${y}</ant_offset_y>
        <ant_offset_z>${z}</ant_offset_z>
        <update_rate>$(arg gps_rate)</update_rate>
        <pub_heading>$(arg pub_heading)</pub_heading>
      </plugin>
    </gazebo>
  </xacro:macro>
  
  <xacro:if value="$(arg gps)" >
    <xacro:gps_antenna link_name="gps" x="1.6" y="0" z="1.45" />
  </xacro:if>

  <gazebo>
    <plugin name="pose_plugin" filename="libpose_plugin.so" >
      <xacro:if value="$(arg pub_tf)">      
        <pub_tf>1</pub_tf>
      </xacro:if>
      <xacro:unless value="$(arg pub_tf)">      
        <pub_tf>0</pub_tf>
      </xacro:unless>
      <xacro:if value="$(arg pub_odom)" >
        <pub_odom>1</pub_odom>
      </xacro:if>
      <xacro:unless value="$(arg pub_odom)" >
        <pub_odom>0</pub_odom>
      </xacro:unless>
      <twist_publish_rate>50.0</twist_publish_rate>
    </plugin>
  </gazebo>
  
  <link name="base_footprint">
      <inertial>
        <origin xyz="1.678053 0 0.815995" rpy="0 0 0"/>
        <mass value="1000.0"/>
        <inertia ixx="50.403343" ixy="0" ixz="0" iyy="115.736679" iyz="0" izz="138.833328"/>
      </inertial>
      <visual name="base_a">
        <origin xyz="1.554524 0 0" rpy="0 0 0"/>
        <geometry>
          <mesh filename="package://audibot_description/meshes/base_a.002.dae" scale="0.01 0.01 0.01"/>
        </geometry>
        <material name="Black.004"/>
      </visual>
      <visual name="base_b">
        <origin xyz="1.554524 0 0" rpy="0 0 0"/>
        <geometry>
          <mesh filename="package://audibot_description/meshes/base_b.002.dae" scale="0.01 0.01 0.01"/>
        </geometry>
        <material name="Glass.002"/>
      </visual>
      <visual name="base_c">
        <origin xyz="1.554524 0 0" rpy="0 0 0"/>
        <geometry>
          <mesh filename="package://audibot_description/meshes/base_c.002.dae" scale="0.01 0.01 0.01"/>
        </geometry>
        <material name="Misc_001"/>
      </visual>
      <visual name="body_a">
        <origin xyz="1.554524 0 0" rpy="0 0 0"/>
        <geometry>
          <mesh filename="package://audibot_description/meshes/body_a.002.dae" scale="0.01 0.01 0.01"/>
        </geometry>
        <material name="Black.004"/>
      </visual>
      <visual name="body_b">
        <origin xyz="1.554524 0 0" rpy="0 0 0"/>
        <geometry>
          <mesh filename="package://audibot_description/meshes/body_b.002.dae" scale="0.01 0.01 0.01"/>
        </geometry>
        <material name="Misc_001"/>
      </visual>
      <visual name="body_c">
        <origin xyz="1.554524 0 0" rpy="0 0 0"/>
        <geometry>
          <mesh filename="package://audibot_description/meshes/body_c.002.dae" scale="0.01 0.01 0.01"/>
        </geometry>
        <material name="Badging.002"/>
      </visual>
      <visual name="body_d">
        <origin xyz="1.554524 0 0" rpy="0 0 0"/>
        <geometry>
          <mesh filename="package://audibot_description/meshes/body_d.002.dae" scale="0.01 0.01 0.01"/>
        </geometry>
        <material name="Bottom.002"/>
      </visual>
      <visual name="body_e">
        <origin xyz="1.554524 0 0" rpy="0 0 0"/>
        <geometry>
          <mesh filename="package://audibot_description/meshes/body_e.002.dae" scale="0.01 0.01 0.01"/>
        </geometry>
        <material name="Body.002"/>
      </visual>
      <visual name="brakelig04">
        <origin xyz="1.554524 0 0" rpy="0 0 0"/>
        <geometry>
          <mesh filename="package://audibot_description/meshes/brakelig04.002.dae" scale="0.01 0.01 0.01"/>
        </geometry>
        <material name="Brakeligh.002"/>
      </visual>
      <visual name="brakelig07">
        <origin xyz="1.554524 0 0" rpy="0 0 0"/>
        <geometry>
          <mesh filename="package://audibot_description/meshes/brakelig07.002.dae" scale="0.01 0.01 0.01"/>
        </geometry>
        <material name="Glass.002"/>
      </visual>
      <visual name="brakelig11">
        <origin xyz="1.554524 0 0" rpy="0 0 0"/>
        <geometry>
          <mesh filename="package://audibot_description/meshes/brakelig11.002.dae" scale="0.01 0.01 0.01"/>
        </geometry>
        <material name="Glass.002"/>
      </visual>
      <visual name="brakelight">
        <origin xyz="1.554524 0 0" rpy="0 0 0"/>
        <geometry>
          <mesh filename="package://audibot_description/meshes/brakelight.002.dae" scale="0.01 0.01 0.01"/>
        </geometry>
        <material name="Brakeligh.002"/>
      </visual>
      <visual name="bumpe">
        <origin xyz="1.554524 0 0" rpy="0 0 0"/>
        <geometry>
          <mesh filename="package://audibot_description/meshes/bumpe.002.dae" scale="0.01 0.01 0.01"/>
        </geometry>
        <material name="Badging.002"/>
      </visual>
      <visual name="bumpe1">
        <origin xyz="1.554524 0 0" rpy="0 0 0"/>
        <geometry>
          <mesh filename="package://audibot_description/meshes/bumpe1.002.dae" scale="0.01 0.01 0.01"/>
        </geometry>
        <material name="Misc_2_001"/>
      </visual>
      <visual name="bumpe2">
        <origin xyz="1.554524 0 0" rpy="0 0 0"/>
        <geometry>
          <mesh filename="package://audibot_description/meshes/bumpe2.002.dae" scale="0.01 0.01 0.01"/>
        </geometry>
        <material name="Chrome.002"/>
      </visual>
      <visual name="bumpe3">
        <origin xyz="1.554524 0 0" rpy="0 0 0"/>
        <geometry>
          <mesh filename="package://audibot_description/meshes/bumpe3.002.dae" scale="0.01 0.01 0.01"/>
        </geometry>
        <material name="Misc_001"/>
      </visual>
      <visual name="bumpe4">
        <origin xyz="1.554524 0 0" rpy="0 0 0"/>
        <geometry>
          <mesh filename="package://audibot_description/meshes/bumpe4.002.dae" scale="0.01 0.01 0.01"/>
        </geometry>
        <material name="Misc_001"/>
      </visual>
      <visual name="bumpe5.000">
        <origin xyz="1.554524 0 0" rpy="0 0 0"/>
        <geometry>
          <mesh filename="package://audibot_description/meshes/bumpe5.002.dae" scale="0.01 0.01 0.01"/>
        </geometry>
        <material name="Body.002"/>
      </visual>
      <visual name="bumpe6">
        <origin xyz="1.554524 0 0" rpy="0 0 0"/>
        <geometry>
          <mesh filename="package://audibot_description/meshes/bumpe6.002.dae" scale="0.01 0.01 0.01"/>
        </geometry>
        <material name="Licens.002"/>
      </visual>
      <visual name="bumper_fro">
        <origin xyz="1.554524 0 0" rpy="0 0 0"/>
        <geometry>
          <mesh filename="package://audibot_description/meshes/bumper_fro.002.dae" scale="0.01 0.01 0.01"/>
        </geometry>
        <material name="Black.004"/>
      </visual>
      <visual name="bumper_r01">
        <origin xyz="1.554524 0 0" rpy="0 0 0"/>
        <geometry>
          <mesh filename="package://audibot_description/meshes/bumper_r01.002.dae" scale="0.01 0.01 0.01"/>
        </geometry>
        <material name="Black.004"/>
      </visual>
      <visual name="bumper_r02">
        <origin xyz="1.554524 0 0" rpy="0 0 0"/>
        <geometry>
          <mesh filename="package://audibot_description/meshes/bumper_r02.002.dae" scale="0.01 0.01 0.01"/>
        </geometry>
        <material name="Brakeligh.002"/>
      </visual>
      <visual name="bumper_r03">
        <origin xyz="1.554524 0 0" rpy="0 0 0"/>
        <geometry>
          <mesh filename="package://audibot_description/meshes/bumper_r03.002.dae" scale="0.01 0.01 0.01"/>
        </geometry>
        <material name="Misc_001"/>
      </visual>
      <visual name="bumper_r04">
        <origin xyz="1.554524 0 0" rpy="0 0 0"/>
        <geometry>
          <mesh filename="package://audibot_description/meshes/bumper_r04.002.dae" scale="0.01 0.01 0.01"/>
        </geometry>
        <material name="Body.002"/>
      </visual>
      <visual name="door_">
        <origin xyz="1.554524 0 0" rpy="0 0 0"/>
        <geometry>
          <mesh filename="package://audibot_description/meshes/door_.002.dae" scale="0.01 0.01 0.01"/>
        </geometry>
        <material name="Badging.002"/>
      </visual>
      <visual name="door_1">
        <origin xyz="1.554524 0 0" rpy="0 0 0"/>
        <geometry>
          <mesh filename="package://audibot_description/meshes/door_1.002.dae" scale="0.01 0.01 0.01"/>
        </geometry>
        <material name="Interior.002"/>
      </visual>
      <visual name="door_2">
        <origin xyz="1.554524 0 0" rpy="0 0 0"/>
        <geometry>
          <mesh filename="package://audibot_description/meshes/door_2.002.dae" scale="0.01 0.01 0.01"/>
        </geometry>
        <material name="Interior.002"/>
      </visual>
      <visual name="door_3">
        <origin xyz="1.554524 0 0" rpy="0 0 0"/>
        <geometry>
          <mesh filename="package://audibot_description/meshes/door_3.002.dae" scale="0.01 0.01 0.01"/>
        </geometry>
        <material name="Badging.002"/>
      </visual>
      <visual name="door_left_">
        <origin xyz="1.554524 0 0" rpy="0 0 0"/>
        <geometry>
          <mesh filename="package://audibot_description/meshes/door_left_.002.dae" scale="0.01 0.01 0.01"/>
        </geometry>
        <material name="Body.002"/>
      </visual>
      <visual name="door_right">
        <origin xyz="1.554524 0 0" rpy="0 0 0"/>
        <geometry>
          <mesh filename="package://audibot_description/meshes/door_right.002.dae" scale="0.01 0.01 0.01"/>
        </geometry>
        <material name="Body.002"/>
      </visual>
      <visual name="exhaust_a">
        <origin xyz="1.554524 0 0" rpy="0 0 0"/>
        <geometry>
          <mesh filename="package://audibot_description/meshes/exhaust_a.002.dae" scale="0.01 0.01 0.01"/>
        </geometry>
        <material name="Black.004"/>
      </visual>
      <visual name="exhaust_b">
        <origin xyz="1.554524 0 0" rpy="0 0 0"/>
        <geometry>
          <mesh filename="package://audibot_description/meshes/exhaust_b.002.dae" scale="0.01 0.01 0.01"/>
        </geometry>
        <material name="Chrome.002"/>
      </visual>
      <visual name="fende">
        <origin xyz="1.554524 0 0" rpy="0 0 0"/>
        <geometry>
          <mesh filename="package://audibot_description/meshes/fende.002.dae" scale="0.01 0.01 0.01"/>
        </geometry>
        <material name="Body.002"/>
      </visual>
      <visual name="fende1">
        <origin xyz="1.554524 0 0" rpy="0 0 0"/>
        <geometry>
          <mesh filename="package://audibot_description/meshes/fende1.002.dae" scale="0.01 0.01 0.01"/>
        </geometry>
        <material name="Body.002"/>
      </visual>
      <visual name="fender_fro">
        <origin xyz="1.554524 0 0" rpy="0 0 0"/>
        <geometry>
          <mesh filename="package://audibot_description/meshes/fender_fro.002.dae" scale="0.01 0.01 0.01"/>
        </geometry>
        <material name="Black.004"/>
      </visual>
      <visual name="headligh03">
        <origin xyz="1.554524 0 0" rpy="0 0 0"/>
        <geometry>
          <mesh filename="package://audibot_description/meshes/headligh03.002.dae" scale="0.01 0.01 0.01"/>
        </geometry>
        <material name="Glass.002"/>
      </visual>
      <visual name="headligh13">
        <origin xyz="1.554524 0 0" rpy="0 0 0"/>
        <geometry>
          <mesh filename="package://audibot_description/meshes/headligh13.002.dae" scale="0.01 0.01 0.01"/>
        </geometry>
        <material name="Headlight.002"/>
      </visual>
      <visual name="headlight_">
        <origin xyz="1.554524 0 0" rpy="0 0 0"/>
        <geometry>
          <mesh filename="package://audibot_description/meshes/headlight_.002.dae" scale="0.01 0.01 0.01"/>
        </geometry>
        <material name="Glass.002"/>
      </visual>
      <visual name="hood_a01">
        <origin xyz="1.554524 0 0" rpy="0 0 0"/>
        <geometry>
          <mesh filename="package://audibot_description/meshes/hood_a01.002.dae" scale="0.01 0.01 0.01"/>
        </geometry>
        <material name="Badging.002"/>
      </visual>
      <visual name="hood_a02">
        <origin xyz="1.554524 0 0" rpy="0 0 0"/>
        <geometry>
          <mesh filename="package://audibot_description/meshes/hood_a02.002.dae" scale="0.01 0.01 0.01"/>
        </geometry>
        <material name="Body.002"/>
      </visual>
      <visual name="sidem">
        <origin xyz="1.554524 0 0" rpy="0 0 0"/>
        <geometry>
          <mesh filename="package://audibot_description/meshes/sidem.002.dae" scale="0.01 0.01 0.01"/>
        </geometry>
        <material name="Body.002"/>
      </visual>
      <visual name="sidem1">
        <origin xyz="1.554524 0 0" rpy="0 0 0"/>
        <geometry>
          <mesh filename="package://audibot_description/meshes/sidem1.002.dae" scale="0.01 0.01 0.01"/>
        </geometry>
        <material name="Body.002"/>
      </visual>
      <visual name="sidemirr04">
        <origin xyz="1.554524 0 0" rpy="0 0 0"/>
        <geometry>
          <mesh filename="package://audibot_description/meshes/sidemirr04.002.dae" scale="0.01 0.01 0.01"/>
        </geometry>
        <material name="Chrome.002"/>
      </visual>
      <visual name="sidemirror">
        <origin xyz="1.554524 0 0" rpy="0 0 0"/>
        <geometry>
          <mesh filename="package://audibot_description/meshes/sidemirror.002.dae" scale="0.01 0.01 0.01"/>
        </geometry>
        <material name="Chrome.002"/>
      </visual>
      <visual name="skirt">
        <origin xyz="1.554524 0 0" rpy="0 0 0"/>
        <geometry>
          <mesh filename="package://audibot_description/meshes/skirt.002.dae" scale="0.01 0.01 0.01"/>
        </geometry>
        <material name="Body.002"/>
      </visual>
      <visual name="skirt1">
        <origin xyz="1.554524 0 0" rpy="0 0 0"/>
        <geometry>
          <mesh filename="package://audibot_description/meshes/skirt1.002.dae" scale="0.01 0.01 0.01"/>
        </geometry>
        <material name="Body.002"/>
      </visual>
      <visual name="skirt_left">
        <origin xyz="1.554524 0 0" rpy="0 0 0"/>
        <geometry>
          <mesh filename="package://audibot_description/meshes/skirt_left.002.dae" scale="0.01 0.01 0.01"/>
        </geometry>
        <material name="Black.004"/>
      </visual>
      <visual name="skirt_righ">
        <origin xyz="1.554524 0 0" rpy="0 0 0"/>
        <geometry>
          <mesh filename="package://audibot_description/meshes/skirt_righ.002.dae" scale="0.01 0.01 0.01"/>
        </geometry>
        <material name="Black.004"/>
      </visual>
      <visual name="trunk_a">
        <origin xyz="1.554524 0 0" rpy="0 0 0"/>
        <geometry>
          <mesh filename="package://audibot_description/meshes/trunk_a.002.dae" scale="0.01 0.01 0.01"/>
        </geometry>
        <material name="Body.002"/>
      </visual>
      <visual name="trunk_b">
        <origin xyz="1.554524 0 0" rpy="0 0 0"/>
        <geometry>
          <mesh filename="package://audibot_description/meshes/trunk_b.002.dae" scale="0.01 0.01 0.01"/>
        </geometry>
        <material name="Black.004"/>
      </visual>
      <visual name="windo">
        <origin xyz="1.554524 0 0" rpy="0 0 0"/>
        <geometry>
          <mesh filename="package://audibot_description/meshes/windo.002.dae" scale="0.01 0.01 0.01"/>
        </geometry>
        <material name="Glass_black_.002"/>
      </visual>
      <visual name="windo1">
        <origin xyz="1.554524 0 0" rpy="0 0 0"/>
        <geometry>
          <mesh filename="package://audibot_description/meshes/windo1.002.dae" scale="0.01 0.01 0.01"/>
        </geometry>
        <material name="Glass_black_.002"/>
      </visual>
      <visual name="window_f04">
        <origin xyz="1.554524 0 0" rpy="0 0 0"/>
        <geometry>
          <mesh filename="package://audibot_description/meshes/window_f04.002.dae" scale="0.01 0.01 0.01"/>
        </geometry>
        <material name="Glass.002"/>
      </visual>
      <visual name="window_f08">
        <origin xyz="1.554524 0 0" rpy="0 0 0"/>
        <geometry>
          <mesh filename="package://audibot_description/meshes/window_f08.002.dae" scale="0.01 0.01 0.01"/>
        </geometry>
        <material name="Glass.002"/>
      </visual>
      <visual name="window_fro">
        <origin xyz="1.554524 0 0" rpy="0 0 0"/>
        <geometry>
          <mesh filename="package://audibot_description/meshes/window_fro.002.dae" scale="0.01 0.01 0.01"/>
        </geometry>
        <material name="Glass.002"/>
      </visual>
      <visual name="window_r04">
        <origin xyz="1.554524 0 0" rpy="0 0 0"/>
        <geometry>
          <mesh filename="package://audibot_description/meshes/window_r04.002.dae" scale="0.01 0.01 0.01"/>
        </geometry>
        <material name="Glass.002"/>
      </visual>
      <visual name="window_r07">
        <origin xyz="1.554524 0 0" rpy="0 0 0"/>
        <geometry>
          <mesh filename="package://audibot_description/meshes/window_r07.002.dae" scale="0.01 0.01 0.01"/>
        </geometry>
        <material name="Glass.002"/>
      </visual>
      <visual name="window_rea">
        <origin xyz="1.554524 0 0" rpy="0 0 0"/>
        <geometry>
          <mesh filename="package://audibot_description/meshes/window_rea.002.dae" scale="0.01 0.01 0.01"/>
        </geometry>
        <material name="Glass.002"/>
      </visual>
      <collision name="chassis_collision">
        <origin xyz="1.398053 0 0.815995" rpy="0 0 0"/>
        <geometry>
          <box size="4.479999 2.1 1.280001"/>
        </geometry>
      </collision>
      <collision name="front_left_bumper">
        <origin xyz="3.898413 0.64447 0.477368" rpy="0 0 0.698132"/>
        <geometry>
          <box size="0.1 0.76 0.4"/>
        </geometry>
      </collision>
      <collision name="front_right_bumper">
        <origin xyz="3.898413 -0.64447 0.477368" rpy="0 0 -0.698132"/>
        <geometry>
          <box size="0.1 0.76 0.4"/>
        </geometry>
      </collision>
    </link>

    <link name="wheel_fl">
      <inertial>
        <origin xyz="0 0 -0.12" rpy="0 0 0"/>
        <mass value="10.0"/>
        <inertia ixx="0.037227" ixy="0" ixz="0" iyy="0.037227" iyz="0" izz="0.063878"/>
      </inertial>
      <visual name="brake1.001">
        <origin xyz="0 0 0" rpy="1.570796 0 0"/>
        <geometry>
          <mesh filename="package://audibot_description/meshes/brake1.005.dae" scale="0.01 0.01 0.01"/>
        </geometry>
        <material name="Brackdisc_001.001"/>
      </visual>
      <visual name="wheel7.001">
        <origin xyz="0 0 0" rpy="1.570796 0 0"/>
        <geometry>
          <mesh filename="package://audibot_description/meshes/wheel7.005.dae" scale="0.01 0.01 0.01"/>
        </geometry>
        <material name="Wheel_001.001"/>
      </visual>
      <visual name="wheel8.001">
        <origin xyz="0 0 0" rpy="1.570796 0 0"/>
        <geometry>
          <mesh filename="package://audibot_description/meshes/wheel8.005.dae" scale="0.01 0.01 0.01"/>
        </geometry>
        <material name="Tire_001.001"/>
      </visual>
      <visual name="wheel_tire.001">
        <origin xyz="0 0 0" rpy="1.570796 0 0"/>
        <geometry>
          <mesh filename="package://audibot_description/meshes/wheel_tire.005.dae" scale="0.01 0.01 0.01"/>
        </geometry>
        <material name="Black_001.001"/>
      </visual>
      <collision name="wheel_fl_collision">
        <origin xyz="0 0 -0.12" rpy="-3.141593 0 0"/>
        <geometry>
          <cylinder radius="0.357429" length="0.251907"/>
        </geometry>
      </collision>
    </link>

    <link name="wheel_fl_steer">
      <inertial>
        <origin xyz="0 0 0" rpy="0 0 0"/>
        <mass value="1.0"/>
        <inertia ixx="0.037227" ixy="0" ixz="0" iyy="0.037227" iyz="0" izz="0.063878"/>
      </inertial>
    </link>

    <link name="wheel_fr">
      <inertial>
        <origin xyz="0 0 0" rpy="1.570796 0 0"/>
        <mass value="10.0"/>
        <inertia ixx="0.037227" ixy="0" ixz="0" iyy="0.037227" iyz="0" izz="0.063878"/>
      </inertial>
      <visual name="brake1.002">
        <origin xyz="0 0 0" rpy="-1.570796 0 0"/>
        <geometry>
          <mesh filename="package://audibot_description/meshes/brake1.000.dae" scale="0.01 0.01 0.01"/>
        </geometry>
        <material name="Brackdisc_001.002"/>
      </visual>
      <visual name="wheel7.002">
        <origin xyz="0 0 0" rpy="-1.570796 0 0"/>
        <geometry>
          <mesh filename="package://audibot_description/meshes/wheel7.000.dae" scale="0.01 0.01 0.01"/>
        </geometry>
        <material name="Wheel_001.002"/>
      </visual>
      <visual name="wheel8.002">
        <origin xyz="0 0 0" rpy="-1.570796 0 0"/>
        <geometry>
          <mesh filename="package://audibot_description/meshes/wheel8.000.dae" scale="0.01 0.01 0.01"/>
        </geometry>
        <material name="Tire_001.002"/>
      </visual>
      <visual name="wheel_tire.002">
        <origin xyz="0 0 0" rpy="-1.570796 0 0"/>
        <geometry>
          <mesh filename="package://audibot_description/meshes/wheel_tire.000.dae" scale="0.01 0.01 0.01"/>
        </geometry>
        <material name="Black_001.002"/>
      </visual>
      <collision name="wheel_fl_collision.001">
        <origin xyz="0 0 0.12" rpy="-3.141593 0 0"/>
        <geometry>
          <cylinder radius="0.357429" length="0.251907"/>
        </geometry>
      </collision>
    </link>

    <link name="wheel_fr_steer">
      <inertial>
        <origin xyz="0 0 0" rpy="0 0 0"/>
        <mass value="1.0"/>
        <inertia ixx="0.037227" ixy="0" ixz="0" iyy="0.037227" iyz="0" izz="0.063878"/>
      </inertial>
    </link>

    <link name="wheel_rl">
      <inertial>
        <origin xyz="0 0 -0.12" rpy="0 0 0"/>
        <mass value="10.0"/>
        <inertia ixx="0.037227" ixy="0" ixz="0" iyy="0.037227" iyz="0" izz="0.063878"/>
      </inertial>
      <visual name="brake1">
        <origin xyz="0 0 0" rpy="1.570796 0 0"/>
        <geometry>
          <mesh filename="package://audibot_description/meshes/brake1.004.dae" scale="0.01 0.01 0.01"/>
        </geometry>
        <material name="Brackdisc_001"/>
      </visual>
      <visual name="wheel7">
        <origin xyz="0 0 0" rpy="1.570796 0 0"/>
        <geometry>
          <mesh filename="package://audibot_description/meshes/wheel7.004.dae" scale="0.01 0.01 0.01"/>
        </geometry>
        <material name="Wheel_001"/>
      </visual>
      <visual name="wheel8">
        <origin xyz="0 0 0" rpy="1.570796 0 0"/>
        <geometry>
          <mesh filename="package://audibot_description/meshes/wheel8.004.dae" scale="0.01 0.01 0.01"/>
        </geometry>
        <material name="Tire_001"/>
      </visual>
      <visual name="wheel_tire">
        <origin xyz="0 0 0" rpy="1.570796 0 0"/>
        <geometry>
          <mesh filename="package://audibot_description/meshes/wheel_tire.004.dae" scale="0.01 0.01 0.01"/>
        </geometry>
        <material name="Black_001"/>
      </visual>
      <collision name="wheel_rl_collision">
        <origin xyz="0 0 -0.12" rpy="-3.141593 0 0"/>
        <geometry>
          <cylinder radius="0.357429" length="0.251907"/>
        </geometry>
      </collision>
    </link>

    <link name="wheel_rr">
      <inertial>
        <origin xyz="0 0 0" rpy="1.570796 0 0"/>
        <mass value="10.0"/>
        <inertia ixx="0.037227" ixy="0" ixz="0" iyy="0.037227" iyz="0" izz="0.063878"/>
      </inertial>
      <visual name="brake1.003">
        <origin xyz="0 0 0" rpy="-1.570796 0 0"/>
        <geometry>
          <mesh filename="package://audibot_description/meshes/brake1.001.dae" scale="0.01 0.01 0.01"/>
        </geometry>
        <material name="Brackdisc_001.003"/>
      </visual>
      <visual name="wheel7.003">
        <origin xyz="0 0 0" rpy="-1.570796 0 0"/>
        <geometry>
          <mesh filename="package://audibot_description/meshes/wheel7.001.dae" scale="0.01 0.01 0.01"/>
        </geometry>
        <material name="Wheel_001.003"/>
      </visual>
      <visual name="wheel8.003">
        <origin xyz="0 0 0" rpy="-1.570796 0 0"/>
        <geometry>
          <mesh filename="package://audibot_description/meshes/wheel8.001.dae" scale="0.01 0.01 0.01"/>
        </geometry>
        <material name="Tire_001.003"/>
      </visual>
      <visual name="wheel_tire.003">
        <origin xyz="0 0 0" rpy="-1.570796 0 0"/>
        <geometry>
          <mesh filename="package://audibot_description/meshes/wheel_tire.001.dae" scale="0.01 0.01 0.01"/>
        </geometry>
        <material name="Black_001.003"/>
      </visual>
      <collision name="wheel_rr_collision">
        <origin xyz="0 0 0.12" rpy="-3.141593 0 0"/>
        <geometry>
          <cylinder radius="0.357429" length="0.251907"/>
        </geometry>
      </collision>
    </link>

    <joint name="wheel_fl" type="continuous">
      <origin xyz="-3e-05 0.11 0" rpy="-1.570796 0 0"/>
      <parent link="wheel_fl_steer"/>
      <child link="wheel_fl"/>
      <axis xyz="0 0 1.0"/>
      <limit effort="0.0" velocity="125.0"/>
    </joint>

    <joint name="wheel_fl_steer" type="revolute">
      <origin xyz="3.0537 0.95 0.36" rpy="0 0 0"/>
      <parent link="base_footprint"/>
      <child link="wheel_fl_steer"/>
      <axis xyz="0 0 1.0"/>
      <limit lower="-0.5" upper="0.5" effort="5000.0" velocity="0.5"/>
    </joint>

    <joint name="wheel_fr" type="continuous">
      <origin xyz="-3e-05 -0.11 0" rpy="-1.570796 0 0"/>
      <parent link="wheel_fr_steer"/>
      <child link="wheel_fr"/>
      <axis xyz="0 0 1.0"/>
      <limit effort="0.0" velocity="125.0"/>
    </joint>

    <joint name="wheel_fr_steer" type="revolute">
      <origin xyz="3.0537 -0.95 0.36" rpy="0 0 0"/>
      <parent link="base_footprint"/>
      <child link="wheel_fr_steer"/>
      <axis xyz="0 0 1.0"/>
      <limit lower="-0.5" upper="0.5" effort="5000.0" velocity="0.5"/>
    </joint>

    <joint name="wheel_rl" type="continuous">
      <origin xyz="0.03 1.08 0.36" rpy="-1.570796 0 0"/>
      <parent link="base_footprint"/>
      <child link="wheel_rl"/>
      <axis xyz="0 0 1.0"/>
      <limit effort="5000.0" velocity="125.0"/>
    </joint>

    <joint name="wheel_rr" type="continuous">
      <origin xyz="0.03 -1.06 0.36" rpy="-1.570796 0 0"/>
      <parent link="base_footprint"/>
      <child link="wheel_rr"/>
      <axis xyz="0 0 1.0"/>
      <limit effort="5000.0" velocity="125.0"/>
    </joint>

    <material name="Badging.002">
      <color rgba="0.398431 0.398431 0.398431 1.0"/>
    </material>

    <material name="Black.004">
      <color rgba="0.078431 0.078431 0.078431 1.0"/>
    </material>

    <material name="Black_001">
      <color rgba="0.078431 0.078431 0.078431 1.0"/>
    </material>

    <material name="Black_001.001">
      <color rgba="0.078431 0.078431 0.078431 1.0"/>
    </material>

    <material name="Black_001.002">
      <color rgba="0.078431 0.078431 0.078431 1.0"/>
    </material>

    <material name="Black_001.003">
      <color rgba="0.078431 0.078431 0.078431 1.0"/>
    </material>

    <material name="Body.002">
      <color rgba="0.345098 0 0 1.0"/>
    </material>

    <material name="Bottom.002">
      <color rgba="0.398431 0.398431 0.398431 1.0"/>
    </material>

    <material name="Brackdisc_001">
      <color rgba="0.398431 0.398431 0.398431 1.0"/>
    </material>

    <material name="Brackdisc_001.001">
      <color rgba="0.398431 0.398431 0.398431 1.0"/>
    </material>

    <material name="Brackdisc_001.002">
      <color rgba="0.398431 0.398431 0.398431 1.0"/>
    </material>

    <material name="Brackdisc_001.003">
      <color rgba="0.398431 0.398431 0.398431 1.0"/>
    </material>

    <material name="Brakeligh.002">
      <color rgba="0.398431 0.398431 0.398431 1.0"/>
    </material>

    <material name="Chrome.002">
      <color rgba="0 0 0 1.0"/>
    </material>

    <material name="Glass.002">
      <color rgba="0.197647 0.197647 0.197647 1.0"/>
    </material>

    <material name="Glass_black_.002">
      <color rgba="0.078431 0.078431 0.078431 1.0"/>
    </material>

    <material name="Headlight.002">
      <color rgba="0.398431 0.398431 0.398431 1.0"/>
    </material>

    <material name="Interior.002">
      <color rgba="0.398431 0.398431 0.398431 1.0"/>
    </material>

    <material name="Licens.002">
      <color rgba="0.398431 0.398431 0.398431 1.0"/>
    </material>

    <material name="Misc_001">
      <color rgba="0.398431 0.398431 0.398431 1.0"/>
    </material>

    <material name="Misc_2_001">
      <color rgba="0.398431 0.398431 0.398431 1.0"/>
    </material>

    <material name="Tire_001">
      <color rgba="0.398431 0.398431 0.398431 1.0"/>
    </material>

    <material name="Tire_001.001">
      <color rgba="0.398431 0.398431 0.398431 1.0"/>
    </material>

    <material name="Tire_001.002">
      <color rgba="0.398431 0.398431 0.398431 1.0"/>
    </material>

    <material name="Tire_001.003">
      <color rgba="0.398431 0.398431 0.398431 1.0"/>
    </material>

    <material name="Wheel_001">
      <color rgba="0.398431 0.398431 0.398431 1.0"/>
    </material>

    <material name="Wheel_001.001">
      <color rgba="0.398431 0.398431 0.398431 1.0"/>
    </material>

    <material name="Wheel_001.002">
      <color rgba="0.398431 0.398431 0.398431 1.0"/>
    </material>

    <material name="Wheel_001.003">
      <color rgba="0.398431 0.398431 0.398431 1.0"/>
    </material>

  </robot>
